Workbook

Sheet Orders_Data
A1: Order_ID | B1: Order_Date | C1: Customer_ID | D1: Product_ID | E1: Product_Nam | F1: Category | G1: Quantity | H1: Unit_Price | I1: Total_Amount | J1: Payment_Met | K1: Payment_Stat | L1: Order_Status | M1: Shipping_City | N1: Delivery_Date | O1: Sales_Channel | P1: Processed_By | Q1: Customer_Check | R1: Duplicate_Check
A2: ORD001 | B2: 45200 | C2: CUST101 | D2: P1001 | E2: =_xlfn.XLOOKUP(D2,Product_Master_Table[Product_ID],Product_Master_Table[Product_Name],"Not Found") -> Laptop | F2: =_xlfn.XLOOKUP(D2,Product_Master_Table[Product_ID],Product_Master_Table[Category],"Not Found") -> Electronics | G2: 1 | H2: =_xlfn.XLOOKUP(D2,Product_Master_Table[Product_ID],Product_Master_Table[Unit_Price],"Not Found") -> 1200 | I2: =H2*G2 -> 1200 | J2: Credit Card | K2: Paid | L2: Delivered | M2: New York | N2: 45204 | O2: Online | P2: Alice_B | Q2: =IF(COUNTIF(Customer_Master_Table[Customer_ID],C2)>0,"Valid","Invalid") -> Valid | R2: =IF(COUNTIF(A2,A2)>1,"Duplicate","Unique") -> Unique
A3: ORD002 | B3: 45200 | C3: CUST102 | D3: P1002 | E3: =_xlfn.XLOOKUP(D3,Product_Master_Table[Product_ID],Product_Master_Table[Product_Name],"Not Found") -> Wireless Mouse | F3: =_xlfn.XLOOKUP(D3,Product_Master_Table[Product_ID],Product_Master_Table[Category],"Not Found") -> Accessories | G3: 2 | H3: =_xlfn.XLOOKUP(D3,Product_Master_Table[Product_ID],Product_Master_Table[Unit_Price],"Not Found") -> 25 | I3: =H3*G3 -> 50 | J3: PayPal | K3: Paid | L3: Delivered | M3: Chicago | N3: 45203 | O3: Online | P3: Bob_M | Q3: =IF(COUNTIF(Customer_Master_Table[Customer_ID],C3)>0,"Valid","Invalid") -> Valid | R3: =IF(COUNTIF(A3,A3)>1,"Duplicate","Unique") -> Unique
A4: ORD003 | B4: 45201 | C4: CUST103 | D4: P1003 | E4: =_xlfn.XLOOKUP(D4,Product_Master_Table[Product_ID],Product_Master_Table[Product_Name],"Not Found") -> Office Chair | F4: =_xlfn.XLOOKUP(D4,Product_Master_Table[Product_ID],Product_Master_Table[Category],"Not Found") -> Furniture | G4: 1 | H4: =_xlfn.XLOOKUP(D4,Product_Master_Table[Product_ID],Product_Master_Table[Unit_Price],"Not Found") -> 150 | I4: =H4*G4 -> 150 | J4: Debit Card | K4: Paid | L4: Shipped | M4: Seattle | N4: 45207 | O4: In-Store | P4: Charlie_D | Q4: =IF(COUNTIF(Customer_Master_Table[Customer_ID],C4)>0,"Valid","Invalid") -> Valid | R4: =IF(COUNTIF(A4,A4)>1,"Duplicate","Unique") -> Unique
A5: ORD004 | B5: 45201 | C5: CUST104 | D5: P1004 | E5: =_xlfn.XLOOKUP(D5,Product_Master_Table[Product_ID],Product_Master_Table[Product_Name],"Not Found") -> Monitor | F5: =_xlfn.XLOOKUP(D5,Product_Master_Table[Product_ID],Product_Master_Table[Category],"Not Found") -> Electronics | G5: 2 | H5: =_xlfn.XLOOKUP(D5,Product_Master_Table[Product_ID],Product_Master_Table[Unit_Price],"Not Found") -> 300 | I5: =H5*G5 -> 600 | J5: Credit Card | K5: Pending | L5: Processing | M5: Austin | N5: 45208 | O5: Online | P5: Alice_B | Q5: =IF(COUNTIF(Customer_Master_Table[Customer_ID],C5)>0,"Valid","Invalid") -> Valid | R5: =IF(COUNTIF(A5,A5)>1,"Duplicate","Unique") -> Unique
A6: ORD005 | B6: 45202 | C6: CUST105 | D6: P1005 | E6: =_xlfn.XLOOKUP(D6,Product_Master_Table[Product_ID],Product_Master_Table[Product_Name],"Not Found") -> Mechanical Keyboard | F6: =_xlfn.XLOOKUP(D6,Product_Master_Table[Product_ID],Product_Master_Table[Category],"Not Found") -> Accessories | G6: 1 | H6: =_xlfn.XLOOKUP(D6,Product_Master_Table[Product_ID],Product_Master_Table[Unit_Price],"Not Found") -> 85 | I6: =H6*G6 -> 85 | J6: PayPal | K6: Paid | L6: Delivered | M6: Denver | N6: 45205 | O6: App | P6: Eva_R | Q6: =IF(COUNTIF(Customer_Master_Table[Customer_ID],C6)>0,"Valid","Invalid") -> Valid | R6: =IF(COUNTIF(A6,A6)>1,"Duplicate","Unique") -> Unique
A7: ORD006 | B7: 45202 | C7: CUST106 | D7: P1006 | E7: =_xlfn.XLOOKUP(D7,Product_Master_Table[Product_ID],Product_Master_Table[Product_Name],"Not Found") -> Standing Desk | F7: =_xlfn.XLOOKUP(D7,Product_Master_Table[Product_ID],Product_Master_Table[Category],"Not Found") -> Furniture | G7: 1 | H7: =_xlfn.XLOOKUP(D7,Product_Master_Table[Product_ID],Product_Master_Table[Unit_Price],"Not Found") -> 450 | I7: =H7*G7 -> 450 | J7: Credit Card | K7: Paid | L7: Shipped | M7: Miami | N7: 45209 | O7: Online | P7: Bob_M | Q7: =IF(COUNTIF(Customer_Master_Table[Customer_ID],C7)>0,"Valid","Invalid") -> Valid | R7: =IF(COUNTIF(A7,A7)>1,"Duplicate","Unique") -> Unique
A8: ORD007 | B8: 45203 | C8: CUST107 | D8: P1007 | E8: =_xlfn.XLOOKUP(D8,Product_Master_Table[Product_ID],Product_Master_Table[Product_Name],"Not Found") -> Smartphone | F8: =_xlfn.XLOOKUP(D8,Product_Master_Table[Product_ID],Product_Master_Table[Category],"Not Found") -> Electronics | G8: 1 | H8: =_xlfn.XLOOKUP(D8,Product_Master_Table[Product_ID],Product_Master_Table[Unit_Price],"Not Found") -> 800 | I8: =H8*G8 -> 800 | J8: Cash | K8: Paid | L8: Delivered | M8: Boston | N8: 45205 | O8: In-Store | P8: Charlie_D | Q8: =IF(COUNTIF(Customer_Master_Table[Customer_ID],C8)>0,"Valid","Invalid") -> Valid | R8: =IF(COUNTIF(A8,A8)>1,"Duplicate","Unique") -> Unique
A9: ORD008 | B9: 45203 | C9: CUST108 | D9: P1008 | E9: =_xlfn.XLOOKUP(D9,Product_Master_Table[Product_ID],Product_Master_Table[Product_Name],"Not Found") -> Headphones | F9: =_xlfn.XLOOKUP(D9,Product_Master_Table[Product_ID],Product_Master_Table[Category],"Not Found") -> Accessories | G9: 3 | H9: =_xlfn.XLOOKUP(D9,Product_Master_Table[Product_ID],Product_Master_Table[Unit_Price],"Not Found") -> 120 | I9: =H9*G9 -> 360 | J9: Credit Card | K9: Failed | L9: Cancelled | M9: Atlanta | N9: N/A | O9: Online | P9: Alice_B | Q9: =IF(COUNTIF(Customer_Master_Table[Customer_ID],C9)>0,"Valid","Invalid") -> Valid | R9: =IF(COUNTIF(A9,A9)>1,"Duplicate","Unique") -> Unique
A10: ORD009 | B10: 45204 | C10: CUST109 | D10: P1009 | E10: =_xlfn.XLOOKUP(D10,Product_Master_Table[Product_ID],Product_Master_Table[Product_Name],"Not Found") -> Tablet | F10: =_xlfn.XLOOKUP(D10,Product_Master_Table[Product_ID],Product_Master_Table[Category],"Not Found") -> Electronics | G10: 2 | H10: =_xlfn.XLOOKUP(D10,Product_Master_Table[Product_ID],Product_Master_Table[Unit_Price],"Not Found") -> 400 | I10: =H10*G10 -> 800 | J10: PayPal | K10: Paid | L10: Processing | M10: Dallas | N10: 45211 | O10: App | P10: Eva_R | Q10: =IF(COUNTIF(Customer_Master_Table[Customer_ID],C10)>0,"Valid","Invalid") -> Valid | R10: =IF(COUNTIF(A10,A10)>1,"Duplicate","Unique") -> Unique
A11: ORD010 | B11: 45204 | C11: CUST110 | D11: P1010 | E11: =_xlfn.XLOOKUP(D11,Product_Master_Table[Product_ID],Product_Master_Table[Product_Name],"Not Found") -> Desk Lamp | F11: =_xlfn.XLOOKUP(D11,Product_Master_Table[Product_ID],Product_Master_Table[Category],"Not Found") -> Furniture | G11: 1 | H11: =_xlfn.XLOOKUP(D11,Product_Master_Table[Product_ID],Product_Master_Table[Unit_Price],"Not Found") -> 45 | I11: =H11*G11 -> 45 | J11: Debit Card | K11: Paid | L11: Shipped | M11: Phoenix | N11: 45210 | O11: Online | P11: Bob_M | Q11: =IF(COUNTIF(Customer_Master_Table[Customer_ID],C11)>0,"Valid","Invalid") -> Valid | R11: =IF(COUNTIF(A11,A11)>1,"Duplicate","Unique") -> Unique
A12: ORD011 | B12: 45205 | C12: CUST111 | D12: P1001 | E12: =_xlfn.XLOOKUP(D12,Product_Master_Table[Product_ID],Product_Master_Table[Product_Name],"Not Found") -> Laptop | F12: =_xlfn.XLOOKUP(D12,Product_Master_Table[Product_ID],Product_Master_Table[Category],"Not Found") -> Electronics | G12: 1 | H12: =_xlfn.XLOOKUP(D12,Product_Master_Table[Product_ID],Product_Master_Table[Unit_Price],"Not Found") -> 1200 | I12: =H12*G12 -> 1200 | J12: Credit Card | K12: Paid | L12: Processing | M12: New York | N12: 45211 | O12: Online | P12: Charlie_D | Q12: =IF(COUNTIF(Customer_Master_Table[Customer_ID],C12)>0,"Valid","Invalid") -> Valid | R12: =IF(COUNTIF(A12,A12)>1,"Duplicate","Unique") -> Unique
A13: ORD012 | B13: 45205 | C13: CUST112 | D13: P1002 | E13: =_xlfn.XLOOKUP(D13,Product_Master_Table[Product_ID],Product_Master_Table[Product_Name],"Not Found") -> Wireless Mouse | F13: =_xlfn.XLOOKUP(D13,Product_Master_Table[Product_ID],Product_Master_Table[Category],"Not Found") -> Accessories | G13: 1 | H13: =_xlfn.XLOOKUP(D13,Product_Master_Table[Product_ID],Product_Master_Table[Unit_Price],"Not Found") -> 25 | I13: =H13*G13 -> 25 | J13: PayPal | K13: Paid | L13: Delivered | M13: Chicago | N13: 45208 | O13: App | P13: Alice_B | Q13: =IF(COUNTIF(Customer_Master_Table[Customer_ID],C13)>0,"Valid","Invalid") -> Valid | R13: =IF(COUNTIF(A13,A13)>1,"Duplicate","Unique") -> Unique
A14: ORD013 | B14: 45206 | C14: CUST113 | D14: P1003 | E14: =_xlfn.XLOOKUP(D14,Product_Master_Table[Product_ID],Product_Master_Table[Product_Name],"Not Found") -> Office Chair | F14: =_xlfn.XLOOKUP(D14,Product_Master_Table[Product_ID],Product_Master_Table[Category],"Not Found") -> Furniture | G14: 4 | H14: =_xlfn.XLOOKUP(D14,Product_Master_Table[Product_ID],Product_Master_Table[Unit_Price],"Not Found") -> 150 | I14: =H14*G14 -> 600 | J14: Bank Transfer | K14: Pending | L14: Processing | M14: Seattle | N14: 45214 | O14: B2B | P14: Eva_R | Q14: =IF(COUNTIF(Customer_Master_Table[Customer_ID],C14)>0,"Valid","Invalid") -> Valid | R14: =IF(COUNTIF(A14,A14)>1,"Duplicate","Unique") -> Unique
A15: ORD014 | B15: 45206 | C15: CUST114 | D15: P1004 | E15: =_xlfn.XLOOKUP(D15,Product_Master_Table[Product_ID],Product_Master_Table[Product_Name],"Not Found") -> Monitor | F15: =_xlfn.XLOOKUP(D15,Product_Master_Table[Product_ID],Product_Master_Table[Category],"Not Found") -> Electronics | G15: 1 | H15: =_xlfn.XLOOKUP(D15,Product_Master_Table[Product_ID],Product_Master_Table[Unit_Price],"Not Found") -> 300 | I15: =H15*G15 -> 300 | J15: Credit Card | K15: Paid | L15: Shipped | M15: Austin | N15: 45211 | O15: Online | P15: Bob_M | Q15: =IF(COUNTIF(Customer_Master_Table[Customer_ID],C15)>0,"Valid","Invalid") -> Valid | R15: =IF(COUNTIF(A15,A15)>1,"Duplicate","Unique") -> Unique
A16: ORD015 | B16: 45207 | C16: CUST115 | D16: P1005 | E16: =_xlfn.XLOOKUP(D16,Product_Master_Table[Product_ID],Product_Master_Table[Product_Name],"Not Found") -> Mechanical Keyboard | F16: =_xlfn.XLOOKUP(D16,Product_Master_Table[Product_ID],Product_Master_Table[Category],"Not Found") -> Accessories | G16: 2 | H16: =_xlfn.XLOOKUP(D16,Product_Master_Table[Product_ID],Product_Master_Table[Unit_Price],"Not Found") -> 85 | I16: =H16*G16 -> 170 | J16: PayPal | K16: Paid | L16: Delivered | M16: Denver | N16: 45210 | O16: App | P16: Charlie_D | Q16: =IF(COUNTIF(Customer_Master_Table[Customer_ID],C16)>0,"Valid","Invalid") -> Valid | R16: =IF(COUNTIF(A16,A16)>1,"Duplicate","Unique") -> Unique
A17: ORD016 | B17: 45207 | C17: CUST116 | D17: P1006 | E17: =_xlfn.XLOOKUP(D17,Product_Master_Table[Product_ID],Product_Master_Table[Product_Name],"Not Found") -> Standing Desk | F17: =_xlfn.XLOOKUP(D17,Product_Master_Table[Product_ID],Product_Master_Table[Category],"Not Found") -> Furniture | G17: 1 | H17: =_xlfn.XLOOKUP(D17,Product_Master_Table[Product_ID],Product_Master_Table[Unit_Price],"Not Found") -> 450 | I17: =H17*G17 -> 450 | J17: Credit Card | K17: Paid | L17: Delivered | M17: Miami | N17: 45213 | O17: Online | P17: Alice_B | Q17: =IF(COUNTIF(Customer_Master_Table[Customer_ID],C17)>0,"Valid","Invalid") -> Valid | R17: =IF(COUNTIF(A17,A17)>1,"Duplicate","Unique") -> Unique
A18: ORD017 | B18: 45208 | C18: CUST117 | D18: P1007 | E18: =_xlfn.XLOOKUP(D18,Product_Master_Table[Product_ID],Product_Master_Table[Product_Name],"Not Found") -> Smartphone | F18: =_xlfn.XLOOKUP(D18,Product_Master_Table[Product_ID],Product_Master_Table[Category],"Not Found") -> Electronics | G18: 2 | H18: =_xlfn.XLOOKUP(D18,Product_Master_Table[Product_ID],Product_Master_Table[Unit_Price],"Not Found") -> 800 | I18: =H18*G18 -> 1600 | J18: Debit Card | K18: Paid | L18: Processing | M18: Boston | N18: 45215 | O18: In-Store | P18: Eva_R | Q18: =IF(COUNTIF(Customer_Master_Table[Customer_ID],C18)>0,"Valid","Invalid") -> Valid | R18: =IF(COUNTIF(A18,A18)>1,"Duplicate","Unique") -> Unique
A19: ORD018 | B19: 45208 | C19: CUST118 | D19: P1008 | E19: =_xlfn.XLOOKUP(D19,Product_Master_Table[Product_ID],Product_Master_Table[Product_Name],"Not Found") -> Headphones | F19: =_xlfn.XLOOKUP(D19,Product_Master_Table[Product_ID],Product_Master_Table[Category],"Not Found") -> Accessories | G19: 1 | H19: =_xlfn.XLOOKUP(D19,Product_Master_Table[Product_ID],Product_Master_Table[Unit_Price],"Not Found") -> 120 | I19: =H19*G19 -> 120 | J19: Credit Card | K19: Paid | L19: Shipped | M19: Atlanta | N19: 45212 | O19: Online | P19: Bob_M | Q19: =IF(COUNTIF(Customer_Master_Table[Customer_ID],C19)>0,"Valid","Invalid") -> Valid | R19: =IF(COUNTIF(A19,A19)>1,"Duplicate","Unique") -> Unique
A20: ORD019 | B20: 45209 | C20: CUST119 | D20: P1009 | E20: =_xlfn.XLOOKUP(D20,Product_Master_Table[Product_ID],Product_Master_Table[Product_Name],"Not Found") -> Tablet | F20: =_xlfn.XLOOKUP(D20,Product_Master_Table[Product_ID],Product_Master_Table[Category],"Not Found") -> Electronics | G20: 1 | H20: =_xlfn.XLOOKUP(D20,Product_Master_Table[Product_ID],Product_Master_Table[Unit_Price],"Not Found") -> 400 | I20: =H20*G20 -> 400 | J20: Cash | K20: Paid | L20: Delivered | M20: Dallas | N20: 45211 | O20: In-Store | P20: Charlie_D | Q20: =IF(COUNTIF(Customer_Master_Table[Customer_ID],C20)>0,"Valid","Invalid") -> Valid | R20: =IF(COUNTIF(A20,A20)>1,"Duplicate","Unique") -> Unique
A21: ORD020 | B21: 45209 | C21: CUST120 | D21: P1010 | E21: =_xlfn.XLOOKUP(D21,Product_Master_Table[Product_ID],Product_Master_Table[Product_Name],"Not Found") -> Desk Lamp | F21: =_xlfn.XLOOKUP(D21,Product_Master_Table[Product_ID],Product_Master_Table[Category],"Not Found") -> Furniture | G21: 3 | H21: =_xlfn.XLOOKUP(D21,Product_Master_Table[Product_ID],Product_Master_Table[Unit_Price],"Not Found") -> 45 | I21: =H21*G21 -> 135 | J21: PayPal | K21: Pending | L21: Processing | M21: Phoenix | N21: 45216 | O21: App | P21: Alice_B | Q21: =IF(COUNTIF(Customer_Master_Table[Customer_ID],C21)>0,"Valid","Invalid") -> Valid | R21: =IF(COUNTIF(A21,A21)>1,"Duplicate","Unique") -> Unique
... A24: ORD023 | B24: 45211 | C24: CUST123 | D24: P1003 | E24: =_xlfn.XLOOKUP(D24,Product_Master_Table[Product_ID],Product_Master_Table[Product_Name],"Not Found") -> Office Chair | F24: =_xlfn.XLOOKUP(D24,Product_Master_Table[Product_ID],Product_Master_Table[Category],"Not Found") -> Furniture | G24: 1 | H24: =_xlfn.XLOOKUP(D24,Product_Master_Table[Product_ID],Product_Master_Table[Unit_Price],"Not Found") -> 150 | I24: =H24*G24 -> 150 | J24: PayPal | K24: Paid | L24: Shipped | M24: Seattle | N24: 45216 | O24: App | P24: Charlie_D | Q24: =IF(COUNTIF(Customer_Master_Table[Customer_ID],C24)>0,"Valid","Invalid") -> Valid | R24: =IF(COUNTIF(A24,A24)>1,"Duplicate","Unique") -> Unique
A25: ORD024 | B25: 45211 | C25: CUST124 | D25: P1004 | E25: =_xlfn.XLOOKUP(D25,Product_Master_Table[Product_ID],Product_Master_Table[Product_Name],"Not Found") -> Monitor | F25: =_xlfn.XLOOKUP(D25,Product_Master_Table[Product_ID],Product_Master_Table[Category],"Not Found") -> Electronics | G25: 1 | H25: =_xlfn.XLOOKUP(D25,Product_Master_Table[Product_ID],Product_Master_Table[Unit_Price],"Not Found") -> 300 | I25: =H25*G25 -> 300 | J25: Debit Card | K25: Failed | L25: Cancelled | M25: Austin | N25: N/A | O25: Online | P25: Alice_B | Q25: =IF(COUNTIF(Customer_Master_Table[Customer_ID],C25)>0,"Valid","Invalid") -> Valid | R25: =IF(COUNTIF(A25,A25)>1,"Duplicate","Unique") -> Unique
A26: ORD025 | B26: 45212 | C26: CUST125 | D26: P1005 | E26: =_xlfn.XLOOKUP(D26,Product_Master_Table[Product_ID],Product_Master_Table[Product_Name],"Not Found") -> Mechanical Keyboard | F26: =_xlfn.XLOOKUP(D26,Product_Master_Table[Product_ID],Product_Master_Table[Category],"Not Found") -> Accessories | G26: 1 | H26: =_xlfn.XLOOKUP(D26,Product_Master_Table[Product_ID],Product_Master_Table[Unit_Price],"Not Found") -> 85 | I26: =H26*G26 -> 85 | J26: Credit Card | K26: Paid | L26: Processing | M26: Denver | N26: 45217 | O26: Online | P26: Eva_R | Q26: =IF(COUNTIF(Customer_Master_Table[Customer_ID],C26)>0,"Valid","Invalid") -> Valid | R26: =IF(COUNTIF(A26,A26)>1,"Duplicate","Unique") -> Unique
A27: ORD026 | B27: 45212 | C27: CUST126 | D27: P1006 | E27: =_xlfn.XLOOKUP(D27,Product_Master_Table[Product_ID],Product_Master_Table[Product_Name],"Not Found") -> Standing Desk | F27: =_xlfn.XLOOKUP(D27,Product_Master_Table[Product_ID],Product_Master_Table[Category],"Not Found") -> Furniture | G27: 2 | H27: =_xlfn.XLOOKUP(D27,Product_Master_Table[Product_ID],Product_Master_Table[Unit_Price],"Not Found") -> 450 | I27: =H27*G27 -> 900 | J27: Bank Transfer | K27: Paid | L27: Shipped | M27: Miami | N27: 45221 | O27: B2B | P27: Bob_M | Q27: =IF(COUNTIF(Customer_Master_Table[Customer_ID],C27)>0,"Valid","Invalid") -> Valid | R27: =IF(COUNTIF(A27,A27)>1,"Duplicate","Unique") -> Unique
A28: ORD027 | B28: 45213 | C28: CUST127 | D28: P1007 | E28: =_xlfn.XLOOKUP(D28,Product_Master_Table[Product_ID],Product_Master_Table[Product_Name],"Not Found") -> Smartphone | F28: =_xlfn.XLOOKUP(D28,Product_Master_Table[Product_ID],Product_Master_Table[Category],"Not Found") -> Electronics | G28: 1 | H28: =_xlfn.XLOOKUP(D28,Product_Master_Table[Product_ID],Product_Master_Table[Unit_Price],"Not Found") -> 800 | I28: =H28*G28 -> 800 | J28: PayPal | K28: Paid | L28: Delivered | M28: Boston | N28: 45217 | O28: App | P28: Charlie_D | Q28: =IF(COUNTIF(Customer_Master_Table[Customer_ID],C28)>0,"Valid","Invalid") -> Valid | R28: =IF(COUNTIF(A28,A28)>1,"Duplicate","Unique") -> Unique
A29: ORD028 | B29: 45213 | C29: CUST128 | D29: P1008 | E29: =_xlfn.XLOOKUP(D29,Product_Master_Table[Product_ID],Product_Master_Table[Product_Name],"Not Found") -> Headphones | F29: =_xlfn.XLOOKUP(D29,Product_Master_Table[Product_ID],Product_Master_Table[Category],"Not Found") -> Accessories | G29: 2 | H29: =_xlfn.XLOOKUP(D29,Product_Master_Table[Product_ID],Product_Master_Table[Unit_Price],"Not Found") -> 120 | I29: =H29*G29 -> 240 | J29: Credit Card | K29: Paid | L29: Processing | M29: Atlanta | N29: 45219 | O29: Online | P29: Alice_B | Q29: =IF(COUNTIF(Customer_Master_Table[Customer_ID],C29)>0,"Valid","Invalid") -> Valid | R29: =IF(COUNTIF(A29,A29)>1,"Duplicate","Unique") -> Unique
A30: ORD029 | B30: 45214 | C30: CUST129 | D30: P1009 | E30: =_xlfn.XLOOKUP(D30,Product_Master_Table[Product_ID],Product_Master_Table[Product_Name],"Not Found") -> Tablet | F30: =_xlfn.XLOOKUP(D30,Product_Master_Table[Product_ID],Product_Master_Table[Category],"Not Found") -> Electronics | G30: 1 | H30: =_xlfn.XLOOKUP(D30,Product_Master_Table[Product_ID],Product_Master_Table[Unit_Price],"Not Found") -> 400 | I30: =H30*G30 -> 400 | J30: Debit Card | K30: Pending | L30: Processing | M30: Dallas | N30: 45220 | O30: Online | P30: Eva_R | Q30: =IF(COUNTIF(Customer_Master_Table[Customer_ID],C30)>0,"Valid","Invalid") -> Valid | R30: =IF(COUNTIF(A30,A30)>1,"Duplicate","Unique") -> Unique
A31: ORD030 | B31: 45214 | C31: CUST130 | D31: P1010 | E31: =_xlfn.XLOOKUP(D31,Product_Master_Table[Product_ID],Product_Master_Table[Product_Name],"Not Found") -> Desk Lamp | F31: =_xlfn.XLOOKUP(D31,Product_Master_Table[Product_ID],Product_Master_Table[Category],"Not Found") -> Furniture | G31: 2 | H31: =_xlfn.XLOOKUP(D31,Product_Master_Table[Product_ID],Product_Master_Table[Unit_Price],"Not Found") -> 45 | I31: =H31*G31 -> 90 | J31: Cash | K31: Paid | L31: Delivered | M31: Phoenix | N31: 45216 | O31: In-Store | P31: Bob_M | Q31: =IF(COUNTIF(Customer_Master_Table[Customer_ID],C31)>0,"Valid","Invalid") -> Valid | R31: =IF(COUNTIF(A31,A31)>1,"Duplicate","Unique") -> Unique
A32: ORD031 | B32: 45215 | C32: CUST131 | D32: P1001 | E32: =_xlfn.XLOOKUP(D32,Product_Master_Table[Product_ID],Product_Master_Table[Product_Name],"Not Found") -> Laptop | F32: =_xlfn.XLOOKUP(D32,Product_Master_Table[Product_ID],Product_Master_Table[Category],"Not Found") -> Electronics | G32: 1 | H32: =_xlfn.XLOOKUP(D32,Product_Master_Table[Product_ID],Product_Master_Table[Unit_Price],"Not Found") -> 1200 | I32: =H32*G32 -> 1200 | J32: Credit Card | K32: Paid | L32: Shipped | M32: New York | N32: 45221 | O32: Online | P32: Charlie_D | Q32: =IF(COUNTIF(Customer_Master_Table[Customer_ID],C32)>0,"Valid","Invalid") -> Valid | R32: =IF(COUNTIF(A32,A32)>1,"Duplicate","Unique") -> Unique
A33: ORD032 | B33: 45215 | C33: CUST132 | D33: P1002 | E33: =_xlfn.XLOOKUP(D33,Product_Master_Table[Product_ID],Product_Master_Table[Product_Name],"Not Found") -> Wireless Mouse | F33: =_xlfn.XLOOKUP(D33,Product_Master_Table[Product_ID],Product_Master_Table[Category],"Not Found") -> Accessories | G33: 3 | H33: =_xlfn.XLOOKUP(D33,Product_Master_Table[Product_ID],Product_Master_Table[Unit_Price],"Not Found") -> 25 | I33: =H33*G33 -> 75 | J33: PayPal | K33: Paid | L33: Delivered | M33: Chicago | N33: 45218 | O33: App | P33: Alice_B | Q33: =IF(COUNTIF(Customer_Master_Table[Customer_ID],C33)>0,"Valid","Invalid") -> Valid | R33: =IF(COUNTIF(A33,A33)>1,"Duplicate","Unique") -> Unique
A34: ORD033 | B34: 45216 | C34: CUST133 | D34: P1003 | E34: =_xlfn.XLOOKUP(D34,Product_Master_Table[Product_ID],Product_Master_Table[Product_Name],"Not Found") -> Office Chair | F34: =_xlfn.XLOOKUP(D34,Product_Master_Table[Product_ID],Product_Master_Table[Category],"Not Found") -> Furniture | G34: 2 | H34: =_xlfn.XLOOKUP(D34,Product_Master_Table[Product_ID],Product_Master_Table[Unit_Price],"Not Found") -> 150 | I34: =H34*G34 -> 300 | J34: Credit Card | K34: Failed | L34: Cancelled | M34: Seattle | N34: N/A | O34: Online | P34: Eva_R | Q34: =IF(COUNTIF(Customer_Master_Table[Customer_ID],C34)>0,"Valid","Invalid") -> Valid | R34: =IF(COUNTIF(A34,A34)>1,"Duplicate","Unique") -> Unique
A35: ORD034 | B35: 45216 | C35: CUST134 | D35: P1004 | E35: =_xlfn.XLOOKUP(D35,Product_Master_Table[Product_ID],Product_Master_Table[Product_Name],"Not Found") -> Monitor | F35: =_xlfn.XLOOKUP(D35,Product_Master_Table[Product_ID],Product_Master_Table[Category],"Not Found") -> Electronics | G35: 1 | H35: =_xlfn.XLOOKUP(D35,Product_Master_Table[Product_ID],Product_Master_Table[Unit_Price],"Not Found") -> 300 | I35: =H35*G35 -> 300 | J35: Cash | K35: Paid | L35: Delivered | M35: Austin | N35: 45218 | O35: In-Store | P35: Bob_M | Q35: =IF(COUNTIF(Customer_Master_Table[Customer_ID],C35)>0,"Valid","Invalid") -> Valid | R35: =IF(COUNTIF(A35,A35)>1,"Duplicate","Unique") -> Unique
A36: ORD035 | B36: 45217 | C36: CUST135 | D36: P1005 | E36: =_xlfn.XLOOKUP(D36,Product_Master_Table[Product_ID],Product_Master_Table[Product_Name],"Not Found") -> Mechanical Keyboard | F36: =_xlfn.XLOOKUP(D36,Product_Master_Table[Product_ID],Product_Master_Table[Category],"Not Found") -> Accessories | G36: 1 | H36: =_xlfn.XLOOKUP(D36,Product_Master_Table[Product_ID],Product_Master_Table[Unit_Price],"Not Found") -> 85 | I36: =H36*G36 -> 85 | J36: PayPal | K36: Paid | L36: Processing | M36: Denver | N36: 45222 | O36: App | P36: Charlie_D | Q36: =IF(COUNTIF(Customer_Master_Table[Customer_ID],C36)>0,"Valid","Invalid") -> Valid | R36: =IF(COUNTIF(A36,A36)>1,"Duplicate","Unique") -> Unique
A37: ORD036 | B37: 45217 | C37: CUST136 | D37: P1006 | E37: =_xlfn.XLOOKUP(D37,Product_Master_Table[Product_ID],Product_Master_Table[Product_Name],"Not Found") -> Standing Desk | F37: =_xlfn.XLOOKUP(D37,Product_Master_Table[Product_ID],Product_Master_Table[Category],"Not Found") -> Furniture | G37: 1 | H37: =_xlfn.XLOOKUP(D37,Product_Master_Table[Product_ID],Product_Master_Table[Unit_Price],"Not Found") -> 450 | I37: =H37*G37 -> 450 | J37: Debit Card | K37: Paid | L37: Shipped | M37: Miami | N37: 45224 | O37: Online | P37: Alice_B | Q37: =IF(COUNTIF(Customer_Master_Table[Customer_ID],C37)>0,"Valid","Invalid") -> Valid | R37: =IF(COUNTIF(A37,A37)>1,"Duplicate","Unique") -> Unique
A38: ORD037 | B38: 45218 | C38: CUST137 | D38: P1007 | E38: =_xlfn.XLOOKUP(D38,Product_Master_Table[Product_ID],Product_Master_Table[Product_Name],"Not Found") -> Smartphone | F38: =_xlfn.XLOOKUP(D38,Product_Master_Table[Product_ID],Product_Master_Table[Category],"Not Found") -> Electronics | G38: 3 | H38: =_xlfn.XLOOKUP(D38,Product_Master_Table[Product_ID],Product_Master_Table[Unit_Price],"Not Found") -> 800 | I38: =H38*G38 -> 2400 | J38: Bank Transfer | K38: Pending | L38: Processing | M38: Boston | N38: 45225 | O38: B2B | P38: Eva_R | Q38: =IF(COUNTIF(Customer_Master_Table[Customer_ID],C38)>0,"Valid","Invalid") -> Valid | R38: =IF(COUNTIF(A38,A38)>1,"Duplicate","Unique") -> Unique
A39: ORD038 | B39: 45218 | C39: CUST138 | D39: P1008 | E39: =_xlfn.XLOOKUP(D39,Product_Master_Table[Product_ID],Product_Master_Table[Product_Name],"Not Found") -> Headphones | F39: =_xlfn.XLOOKUP(D39,Product_Master_Table[Product_ID],Product_Master_Table[Category],"Not Found") -> Accessories | G39: 1 | H39: =_xlfn.XLOOKUP(D39,Product_Master_Table[Product_ID],Product_Master_Table[Unit_Price],"Not Found") -> 120 | I39: =H39*G39 -> 120 | J39: Credit Card | K39: Paid | L39: Delivered | M39: Atlanta | N39: 45221 | O39: Online | P39: Bob_M | Q39: =IF(COUNTIF(Customer_Master_Table[Customer_ID],C39)>0,"Valid","Invalid") -> Valid | R39: =IF(COUNTIF(A39,A39)>1,"Duplicate","Unique") -> Unique
A40: ORD039 | B40: 45219 | C40: CUST139 | D40: P1009 | E40: =_xlfn.XLOOKUP(D40,Product_Master_Table[Product_ID],Product_Master_Table[Product_Name],"Not Found") -> Tablet | F40: =_xlfn.XLOOKUP(D40,Product_Master_Table[Product_ID],Product_Master_Table[Category],"Not Found") -> Electronics | G40: 2 | H40: =_xlfn.XLOOKUP(D40,Product_Master_Table[Product_ID],Product_Master_Table[Unit_Price],"Not Found") -> 400 | I40: =H40*G40 -> 800 | J40: PayPal | K40: Paid | L40: Shipped | M40: Dallas | N40: 45225 | O40: App | P40: Charlie_D | Q40: =IF(COUNTIF(Customer_Master_Table[Customer_ID],C40)>0,"Valid","Invalid") -> Valid | R40: =IF(COUNTIF(A40,A40)>1,"Duplicate","Unique") -> Unique
A41: ORD040 | B41: 45219 | C41: CUST140 | D41: P1010 | E41: =_xlfn.XLOOKUP(D41,Product_Master_Table[Product_ID],Product_Master_Table[Product_Name],"Not Found") -> Desk Lamp | F41: =_xlfn.XLOOKUP(D41,Product_Master_Table[Product_ID],Product_Master_Table[Category],"Not Found") -> Furniture | G41: 1 | H41: =_xlfn.XLOOKUP(D41,Product_Master_Table[Product_ID],Product_Master_Table[Unit_Price],"Not Found") -> 45 | I41: =H41*G41 -> 45 | J41: Cash | K41: Paid | L41: Delivered | M41: Phoenix | N41: 45220 | O41: In-Store | P41: Alice_B | Q41: =IF(COUNTIF(Customer_Master_Table[Customer_ID],C41)>0,"Valid","Invalid") -> Valid | R41: =IF(COUNTIF(A41,A41)>1,"Duplicate","Unique") -> Unique
A42: ORD041 | B42: 45220 | C42: CUST141 | D42: P1001 | E42: =_xlfn.XLOOKUP(D42,Product_Master_Table[Product_ID],Product_Master_Table[Product_Name],"Not Found") -> Laptop | F42: =_xlfn.XLOOKUP(D42,Product_Master_Table[Product_ID],Product_Master_Table[Category],"Not Found") -> Electronics | G42: 2 | H42: =_xlfn.XLOOKUP(D42,Product_Master_Table[Product_ID],Product_Master_Table[Unit_Price],"Not Found") -> 1200 | I42: =H42*G42 -> 2400 | J42: Credit Card | K42: Paid | L42: Processing | M42: New York | N42: 45227 | O42: Online | P42: Eva_R | Q42: =IF(COUNTIF(Customer_Master_Table[Customer_ID],C42)>0,"Valid","Invalid") -> Valid | R42: =IF(COUNTIF(A42,A42)>1,"Duplicate","Unique") -> Unique
...

Sheet Customer_Master
A1: Customer_ID | B1: Customer_Name | C1: Gender | D1: Age | E1: Phone | F1: Email | G1: City | H1: Customer_Type
A2: CUST101 | B2: Rahul Sharma | C2: Male | D2: 28 | E2: 9876501001 | F2: rahul@gmail.com | G2: New York | H2: Regular
A3: CUST102 | B3: Priya Verma | C3: Female | D3: 25 | E3: 9876501002 | F3: priya@gmail.com | G3: Chicago | H3: Premium
A4: CUST103 | B4: Amit Singh | C4: Male | D4: 32 | E4: 9876501003 | F4: amit@gmail.com | G4: Seattle | H4: Regular
A5: CUST104 | B5: Neha Gupta | C5: Female | D5: 27 | E5: 9876501004 | F5: neha@gmail.com | G5: Austin | H5: New
A6: CUST105 | B6: Rohit Jain | C6: Male | D6: 35 | E6: 9876501005 | F6: rohit@gmail.com | G6: Denver | H6: Premium
A7: CUST106 | B7: Anjali Mehta | C7: Female | D7: 29 | E7: 9876501006 | F7: anjali@gmail.com | G7: Miami | H7: Regular
A8: CUST107 | B8: Karan Patel | C8: Male | D8: 31 | E8: 9876501007 | F8: karan@gmail.com | G8: Boston | H8: Premium
A9: CUST108 | B9: Sneha Kapoor | C9: Female | D9: 24 | E9: 9876501008 | F9: sneha@gmail.com | G9: Atlanta | H9: New
A10: CUST109 | B10: Arjun Malhotra | C10: Male | D10: 30 | E10: 9876501009 | F10: arjun@gmail.com | G10: Dallas | H10: Regular
A11: CUST110 | B11: Pooja Sharma | C11: Female | D11: 26 | E11: 9876501010 | F11: pooja@gmail.com | G11: Phoenix | H11: New
A12: CUST111 | B12: Riya Kapoor | C12: Female | D12: 28 | E12: 9876501011 | F12: riya@gmail.com | G12: New York | H12: Regular
A13: CUST112 | B13: Vikash Kumar | C13: Male | D13: 34 | E13: 9876501012 | F13: vikash@gmail.com | G13: Chicago | H13: Premium
... A51: CUST150 | B51: Sandeep Gupta | C51: Male | D51: 33 | E51: 9876501050 | F51: sandeep@gmail.com | G51: Denver | H51: Premium

Sheet Product_Master
A1: Product_ID | B1: Product_Name | C1: Category | D1: Unit_Price | E1: Stock_Available | F1: Supplier | G1: Reorder_Level
A2: P1001 | B2: Laptop | C2: Electronics | D2: 1200 | E2: 25 | F2: TechWorld | G2: 10
A3: P1002 | B3: Wireless Mouse | C3: Accessories | D3: 25 | E3: 80 | F3: AccessPro | G3: 20
A4: P1003 | B4: Office Chair | C4: Furniture | D4: 150 | E4: 15 | F4: FurniMart | G4: 5
A5: P1004 | B5: Monitor | C5: Electronics | D5: 300 | E5: 30 | F5: TechWorld | G5: 10
A6: P1005 | B6: Mechanical Keyboard | C6: Accessories | D6: 85 | E6: 45 | F6: AccessPro | G6: 15
A7: P1006 | B7: Standing Desk | C7: Furniture | D7: 450 | E7: 12 | F7: FurniMart | G7: 5
A8: P1007 | B8: Smartphone | C8: Electronics | D8: 800 | E8: 20 | F8: MobileHub | G8: 8
A9: P1008 | B9: Headphones | C9: Accessories | D9: 120 | E9: 60 | F9: AudioTech | G9: 15
A10: P1009 | B10: Tablet | C10: Electronics | D10: 400 | E10: 18 | F10: MobileHub | G10: 7
A11: P1010 | B11: Desk Lamp | C11: Furniture | D11: 45 | E11: 50 | F11: HomeSupply | G11: 15

Sheet MIS_Report
A1: ORDER PROCESSING MIS REPORT | D1: ORDER STATUS | E1: ORDER COUNT | G1: SALES CHANNEL | H1: ORDER COUNT | J1: CATEGORY | K1: ORDER COUNT
A3: Total Orders | B3: =COUNTA(Orders_Data[Order_ID]) -> 50 | D3: Delivered | E3: =COUNTIF(Orders_Data[Order_Status],D3) -> 18 | G3: Online | H3: =COUNTIF(Orders_Data[Sales_Channel],G3) -> 24 | J3: Electronics | K3: =COUNTIF(Orders_Data[Category],J3) -> 20
A4: Total Sales | B4: =SUM(Orders_Data[Total_Amount]) -> 30440 | D4: Processing | E4: =COUNTIF(Orders_Data[Order_Status],D4) -> 14 | G4: In-Store | H4: =COUNTIF(Orders_Data[Sales_Channel],G4) -> 8 | J4: Accessories | K4: =COUNTIF(Orders_Data[Category],J4) -> 15
A5: Delivered Orders | B5: =COUNTIF(Orders_Data[Order_Status],"Delivered") -> 18 | D5: Shipped | E5: =COUNTIF(Orders_Data[Order_Status],D5) -> 14 | G5: App | H5: =COUNTIF(Orders_Data[Sales_Channel],G5) -> 13 | J5: Furniture | K5: =COUNTIF(Orders_Data[Category],J5) -> 15
A6: Processing Orders | B6: =COUNTIF(Orders_Data[Order_Status],"Processing") -> 14 | D6: Pending | E6: =COUNTIF(Orders_Data[Order_Status],D6) -> 0 | G6: B2B | H6: =COUNTIF(Orders_Data[Sales_Channel],G6) -> 5
A7: Shipped Orders | B7: =COUNTIF(Orders_Data[Order_Status],"Shipped") -> 14 | D7: Cancelled | E7: =COUNTIF(Orders_Data[Order_Status],D7) -> 4
A8: Pending Orders | B8: =COUNTIF(Orders_Data[Order_Status],"Pending") -> 0 | G8: SALES CHANNEL | H8: TOTAL SALES | J8: CATEGORY | K8: TOTAL SALES
A9: Cancelled Orders | B9: =COUNTIF(Orders_Data[Order_Status],"Cancelled") -> 4 | G9: Online | H9: =SUMIF(Orders_Data[Sales_Channel],G9,Orders_Data[Total_Amount]) -> 11370 | J9: Electronics | K9: =SUMIFS(Orders_Data[Total_Amount],Orders_Data[Category],J9) -> 23300
A10: Pending Payments | B10: =COUNTIF(Orders_Data[Payment_Stat],"Pending") -> 6 | D10: PAYMENT STATUS | E10: ORDER COUNT | G10: In-Store | H10: =SUMIF(Orders_Data[Sales_Channel],G10,Orders_Data[Total_Amount]) -> 4185 | J10: Accessories | K10: =SUMIFS(Orders_Data[Total_Amount],Orders_Data[Category],J10) -> 1695
A11: Failed Payments | B11: =COUNTIF(Orders_Data[Payment_Stat],"Failed") -> 4 | D11: Paid | E11: =COUNTIF(Orders_Data[Payment_Stat],D11) -> 40 | G11: App | H11: =SUMIF(Orders_Data[Sales_Channel],G11,Orders_Data[Total_Amount]) -> 3635 | J11: Furniture | K11: =SUMIFS(Orders_Data[Total_Amount],Orders_Data[Category],J11) -> 5445
A12: Average Order Value | B12: =AVERAGE(Orders_Data[Total_Amount]) -> 608.8 | D12: Pending | E12: =COUNTIF(Orders_Data[Payment_Stat],D12) -> 6 | G12: B2B | H12: =SUMIF(Orders_Data[Sales_Channel],G12,Orders_Data[Total_Amount]) -> 11250
D13: Failed | E13: =COUNTIF(Orders_Data[Payment_Stat],D13) -> 4
D14: Refunded | E14: =COUNTIF(Orders_Data[Payment_Stat],D14) -> 0

Sheet Dashboard
A1: ORDER PROCESSING & OPERATIONS DASHBOARD
A3: TOTAL ORDERS | C3: TOTAL SALES | E3: DELIVERED | G3: PROCESSING | I3: SHIPPED | K3: CANCELLED
A4: =MIS_Report!B3 -> 50 | C4: =MIS_Report!B4 -> 30440 | E4: =MIS_Report!B5 -> 18 | G4: =MIS_Report!B6 -> 14 | I4: =MIS_Report!B7 -> 14 | K4: =MIS_Report!B9 -> 4
A52: Sales Channel | B52: Order Count | D52: Order Status | E52: Order Count | G52: Sales Channel | H52: Total Sales | J52: Category | K52: Total Sales
A53: Online | B53: =MIS_Report!H3 -> 24 | D53: Delivered | E53: =MIS_Report!E3 -> 18 | G53: Online | H53: =MIS_Report!H9 -> 11370 | J53: Electronics | K53: =MIS_Report!K9 -> 23300
A54: In-Store | B54: =MIS_Report!H4 -> 8 | D54: Processing | E54: =MIS_Report!E4 -> 14 | G54: In-Store | H54: =MIS_Report!H10 -> 4185 | J54: Accessories | K54: =MIS_Report!K10 -> 1695
A55: App | B55: =MIS_Report!H5 -> 13 | D55: Shipped | E55: =MIS_Report!E5 -> 14 | G55: App | H55: =MIS_Report!H11 -> 3635 | J55: Furniture | K55: =MIS_Report!K11 -> 5445
A56: B2B | B56: =MIS_Report!H6 -> 5 | D56: Pending | E56: =MIS_Report!E6 -> 0 | G56: B2B | H56: =MIS_Report!H12 -> 11250
D57: Cancelled | E57: =MIS_Report!E7 -> 4
